2017-05-11 20:19:03,007 (35444/MainThread) pgcli.main INFO - Default pager found in PAGER environment variable: 'less'
2017-05-11 20:19:03,016 (35444/MainThread) pgcli.main ERROR - traceback: 'Traceback (most recent call last):\n  File "/usr/local/Cellar/pgcli/1.5.1/libexec/lib/python2.7/site-packages/pgcli/main.py", line 330, in connect\n    raise e\nOperationalError: could not connect to server: No such file or directory\n\tIs the server running locally and accepting\n\tconnections on Unix domain socket "/var/pgsql_socket/.s.PGSQL.5432"?\n\n'
2017-05-11 20:19:13,849 (35465/MainThread) pgcli.main INFO - Default pager found in PAGER environment variable: 'less'
2017-05-11 20:19:13,853 (35465/MainThread) pgcli.main ERROR - traceback: 'Traceback (most recent call last):\n  File "/usr/local/Cellar/pgcli/1.5.1/libexec/lib/python2.7/site-packages/pgcli/main.py", line 330, in connect\n    raise e\nOperationalError: could not connect to server: No such file or directory\n\tIs the server running locally and accepting\n\tconnections on Unix domain socket "/var/pgsql_socket/.s.PGSQL.5432"?\n\n'
2017-05-11 20:27:38,864 (35590/MainThread) pgcli.main INFO - Default pager found in PAGER environment variable: 'less'
2017-05-11 20:28:08,583 (35667/MainThread) pgcli.main INFO - Default pager found in PAGER environment variable: 'less'
2017-05-11 21:42:22,883 (36404/MainThread) pgcli.main INFO - Default pager found in PAGER environment variable: 'less'
2017-05-11 21:48:05,056 (36464/MainThread) pgcli.main INFO - Default pager found in PAGER environment variable: 'less'
2017-05-15 17:33:46,362 (38752/MainThread) pgcli.main INFO - Default pager found in PAGER environment variable: 'less'
2017-05-15 17:36:47,857 (38797/MainThread) pgcli.main INFO - Default pager found in PAGER environment variable: 'less'
2017-05-15 21:20:20,028 (40391/MainThread) pgcli.main INFO - Default pager found in PAGER environment variable: 'less'
2017-05-15 21:29:14,408 (40608/MainThread) pgcli.main INFO - Default pager found in PAGER environment variable: 'less'
2017-05-15 21:35:30,130 (40608/MainThread) pgcli.pgexecute ERROR - sql: u'create table temp_table()', error: InternalError('cannot execute CREATE TABLE in a read-only transaction\n',)
2017-05-15 21:35:30,134 (40608/MainThread) pgcli.pgexecute ERROR - traceback: 'Traceback (most recent call last):\n  File "/usr/local/Cellar/pgcli/1.5.1/libexec/lib/python2.7/site-packages/pgcli/pgexecute.py", line 294, in run\n    yield self.execute_normal_sql(sql) + (sql, True)\n  File "/usr/local/Cellar/pgcli/1.5.1/libexec/lib/python2.7/site-packages/pgcli/pgexecute.py", line 314, in execute_normal_sql\n    cur.execute(split_sql)\nInternalError: cannot execute CREATE TABLE in a read-only transaction\n\n'
2017-05-15 21:35:56,604 (40694/MainThread) pgcli.main INFO - Default pager found in PAGER environment variable: 'less'
2017-05-15 21:36:02,253 (40714/MainThread) pgcli.main INFO - Default pager found in PAGER environment variable: 'less'
2017-05-15 21:36:02,263 (40714/MainThread) pgcli.main ERROR - traceback: 'Traceback (most recent call last):\n  File "/usr/local/Cellar/pgcli/1.5.1/libexec/lib/python2.7/site-packages/pgcli/main.py", line 330, in connect\n    raise e\nOperationalError: could not connect to server: No such file or directory\n\tIs the server running locally and accepting\n\tconnections on Unix domain socket "/var/pgsql_socket/.s.PGSQL.5432"?\n\n'
2017-05-15 21:37:36,665 (40862/MainThread) pgcli.main INFO - Default pager found in PAGER environment variable: 'less'
2017-05-15 21:38:37,091 (40862/MainThread) pgcli.pgexecute ERROR - sql: u'create table temp_table ()', error: ProgrammingError('relation "temp_table" already exists\n',)
2017-05-15 21:38:37,092 (40862/MainThread) pgcli.pgexecute ERROR - traceback: 'Traceback (most recent call last):\n  File "/usr/local/Cellar/pgcli/1.5.1/libexec/lib/python2.7/site-packages/pgcli/pgexecute.py", line 294, in run\n    yield self.execute_normal_sql(sql) + (sql, True)\n  File "/usr/local/Cellar/pgcli/1.5.1/libexec/lib/python2.7/site-packages/pgcli/pgexecute.py", line 314, in execute_normal_sql\n    cur.execute(split_sql)\nProgrammingError: relation "temp_table" already exists\n\n'
2017-05-15 21:41:46,744 (40922/MainThread) pgcli.main INFO - Default pager found in PAGER environment variable: 'less'
2017-05-15 21:41:58,767 (40943/MainThread) pgcli.main INFO - Default pager found in PAGER environment variable: 'less'
2017-05-15 21:42:02,130 (40963/MainThread) pgcli.main INFO - Default pager found in PAGER environment variable: 'less'
2017-05-15 21:45:14,121 (40963/MainThread) pgcli.pgexecute ERROR - sql: u"COPY temp_endpoint_table FROM '/Users/kumaresan/Downloads/endpoint_list.csv' DELIMITER ',' CSV", error: ProgrammingError("must be superuser to COPY to or from a file\nHINT:  Anyone can COPY to stdout or from stdin. psql's \\copy command also works for anyone.\n",)
2017-05-15 21:45:14,125 (40963/MainThread) pgcli.pgexecute ERROR - traceback: 'Traceback (most recent call last):\n  File "/usr/local/Cellar/pgcli/1.5.1/libexec/lib/python2.7/site-packages/pgcli/pgexecute.py", line 294, in run\n    yield self.execute_normal_sql(sql) + (sql, True)\n  File "/usr/local/Cellar/pgcli/1.5.1/libexec/lib/python2.7/site-packages/pgcli/pgexecute.py", line 314, in execute_normal_sql\n    cur.execute(split_sql)\nProgrammingError: must be superuser to COPY to or from a file\nHINT:  Anyone can COPY to stdout or from stdin. psql\'s \\copy command also works for anyone.\n\n'
2017-05-15 21:45:42,590 (40963/MainThread) pgcli.pgexecute ERROR - sql: u"\\copy temp_endpoint_table FROM '/Users/kumaresan/Downloads/endpoint_list.csv' DELIMITER ',' CSV", error: DataError('extra data after last expected column\nCONTEXT:  COPY temp_endpoint_table, line 1: "18979552819488"\n',)
2017-05-15 21:45:42,593 (40963/MainThread) pgcli.pgexecute ERROR - traceback: 'Traceback (most recent call last):\n  File "/usr/local/Cellar/pgcli/1.5.1/libexec/lib/python2.7/site-packages/pgcli/pgexecute.py", line 283, in run\n    for result in pgspecial.execute(cur, sql):\n  File "/usr/local/Cellar/pgcli/1.5.1/libexec/vendor/lib/python2.7/site-packages/pgspecial/main.py", line 88, in execute\n    return special_cmd.handler(cur=cur, pattern=pattern, verbose=verbose)\n  File "/usr/local/Cellar/pgcli/1.5.1/libexec/vendor/lib/python2.7/site-packages/pgspecial/iocommands.py", line 139, in copy\n    cur.copy_expert(\'copy \' + query, file)\nDataError: extra data after last expected column\nCONTEXT:  COPY temp_endpoint_table, line 1: "18979552819488"\n\n'
2017-05-15 21:47:06,967 (40963/MainThread) pgcli.pgexecute ERROR - sql: u'create table temp_endpoint_table (id interger)', error: ProgrammingError('type "interger" does not exist\nLINE 1: create table temp_endpoint_table (id interger)\n                                             ^\n',)
2017-05-15 21:47:06,970 (40963/MainThread) pgcli.pgexecute ERROR - traceback: 'Traceback (most recent call last):\n  File "/usr/local/Cellar/pgcli/1.5.1/libexec/lib/python2.7/site-packages/pgcli/pgexecute.py", line 294, in run\n    yield self.execute_normal_sql(sql) + (sql, True)\n  File "/usr/local/Cellar/pgcli/1.5.1/libexec/lib/python2.7/site-packages/pgcli/pgexecute.py", line 314, in execute_normal_sql\n    cur.execute(split_sql)\nProgrammingError: type "interger" does not exist\nLINE 1: create table temp_endpoint_table (id interger)\n                                             ^\n\n'
2017-05-15 21:47:20,177 (40963/MainThread) pgcli.pgexecute ERROR - sql: u"\\copy temp_endpoint_table FROM '/Users/kumaresan/Downloads/endpoint_list.csv' DELIMITER ',' CSV", error: DataError('value "18979552819488" is out of range for type integer\nCONTEXT:  COPY temp_endpoint_table, line 1, column id: "18979552819488"\n',)
2017-05-15 21:47:20,178 (40963/MainThread) pgcli.pgexecute ERROR - traceback: 'Traceback (most recent call last):\n  File "/usr/local/Cellar/pgcli/1.5.1/libexec/lib/python2.7/site-packages/pgcli/pgexecute.py", line 283, in run\n    for result in pgspecial.execute(cur, sql):\n  File "/usr/local/Cellar/pgcli/1.5.1/libexec/vendor/lib/python2.7/site-packages/pgspecial/main.py", line 88, in execute\n    return special_cmd.handler(cur=cur, pattern=pattern, verbose=verbose)\n  File "/usr/local/Cellar/pgcli/1.5.1/libexec/vendor/lib/python2.7/site-packages/pgspecial/iocommands.py", line 139, in copy\n    cur.copy_expert(\'copy \' + query, file)\nDataError: value "18979552819488" is out of range for type integer\nCONTEXT:  COPY temp_endpoint_table, line 1, column id: "18979552819488"\n\n'
2017-05-15 21:47:39,838 (40963/MainThread) pgcli.pgexecute ERROR - sql: u"\\copy temp_endpoint_table(id) FROM '/Users/kumaresan/Downloads/endpoint_list.csv' DELIMITER ',' CSV", error: DataError('value "18979552819488" is out of range for type integer\nCONTEXT:  COPY temp_endpoint_table, line 1, column id: "18979552819488"\n',)
2017-05-15 21:47:39,841 (40963/MainThread) pgcli.pgexecute ERROR - traceback: 'Traceback (most recent call last):\n  File "/usr/local/Cellar/pgcli/1.5.1/libexec/lib/python2.7/site-packages/pgcli/pgexecute.py", line 283, in run\n    for result in pgspecial.execute(cur, sql):\n  File "/usr/local/Cellar/pgcli/1.5.1/libexec/vendor/lib/python2.7/site-packages/pgspecial/main.py", line 88, in execute\n    return special_cmd.handler(cur=cur, pattern=pattern, verbose=verbose)\n  File "/usr/local/Cellar/pgcli/1.5.1/libexec/vendor/lib/python2.7/site-packages/pgspecial/iocommands.py", line 139, in copy\n    cur.copy_expert(\'copy \' + query, file)\nDataError: value "18979552819488" is out of range for type integer\nCONTEXT:  COPY temp_endpoint_table, line 1, column id: "18979552819488"\n\n'
2017-05-15 21:55:00,372 (41152/MainThread) pgcli.main INFO - Default pager found in PAGER environment variable: 'less'
2017-05-16 14:54:20,162 (41836/MainThread) pgcli.main INFO - Default pager found in PAGER environment variable: 'less'
2017-05-16 15:13:10,166 (41836/MainThread) pgcli.pgexecute ERROR - sql: u'select * from plivo_product_recharge_plan where productplan_id = 538', error: ProgrammingError('relation "plivo_product_recharge_plan" does not exist\nLINE 1: select * from plivo_product_recharge_plan where productplan_...\n                      ^\n',)
2017-05-16 15:13:10,173 (41836/MainThread) pgcli.pgexecute ERROR - traceback: 'Traceback (most recent call last):\n  File "/usr/local/Cellar/pgcli/1.5.1/libexec/lib/python2.7/site-packages/pgcli/pgexecute.py", line 294, in run\n    yield self.execute_normal_sql(sql) + (sql, True)\n  File "/usr/local/Cellar/pgcli/1.5.1/libexec/lib/python2.7/site-packages/pgcli/pgexecute.py", line 314, in execute_normal_sql\n    cur.execute(split_sql)\nProgrammingError: relation "plivo_product_recharge_plan" does not exist\nLINE 1: select * from plivo_product_recharge_plan where productplan_...\n                      ^\n\n'
2017-05-16 15:25:05,896 (41836/MainThread) pgcli.pgexecute ERROR - sql: u'select * from plivo_account_credit where id=67241', error: ProgrammingError('relation "plivo_account_credit" does not exist\nLINE 1: select * from plivo_account_credit where id=67241\n                      ^\n',)
2017-05-16 15:25:05,899 (41836/MainThread) pgcli.pgexecute ERROR - traceback: 'Traceback (most recent call last):\n  File "/usr/local/Cellar/pgcli/1.5.1/libexec/lib/python2.7/site-packages/pgcli/pgexecute.py", line 294, in run\n    yield self.execute_normal_sql(sql) + (sql, True)\n  File "/usr/local/Cellar/pgcli/1.5.1/libexec/lib/python2.7/site-packages/pgcli/pgexecute.py", line 314, in execute_normal_sql\n    cur.execute(split_sql)\nProgrammingError: relation "plivo_account_credit" does not exist\nLINE 1: select * from plivo_account_credit where id=67241\n                      ^\n\n'
2017-05-16 15:25:18,315 (41836/MainThread) pgcli.pgexecute ERROR - sql: u'select * from plivo_log_accountcredit where id=67241', error: ProgrammingError('relation "plivo_log_accountcredit" does not exist\nLINE 1: select * from plivo_log_accountcredit where id=67241\n                      ^\n',)
2017-05-16 15:25:18,316 (41836/MainThread) pgcli.pgexecute ERROR - traceback: 'Traceback (most recent call last):\n  File "/usr/local/Cellar/pgcli/1.5.1/libexec/lib/python2.7/site-packages/pgcli/pgexecute.py", line 294, in run\n    yield self.execute_normal_sql(sql) + (sql, True)\n  File "/usr/local/Cellar/pgcli/1.5.1/libexec/lib/python2.7/site-packages/pgcli/pgexecute.py", line 314, in execute_normal_sql\n    cur.execute(split_sql)\nProgrammingError: relation "plivo_log_accountcredit" does not exist\nLINE 1: select * from plivo_log_accountcredit where id=67241\n                      ^\n\n'
2017-05-16 15:25:40,686 (42137/MainThread) pgcli.main INFO - Default pager found in PAGER environment variable: 'less'
2017-05-17 15:53:12,912 (46516/MainThread) pgcli.main INFO - Default pager found in PAGER environment variable: 'less'
2017-05-17 15:53:40,660 (46516/MainThread) pgcli.pgexecute ERROR - sql: u"\\copy temp_endpoint_table(id) FROM '/Users/kumaresan/Downloads/endpoint_list.csv' DELIMITER ',' CSV", error: ProgrammingError('relation "temp_endpoint_table" does not exist\n',)
2017-05-17 15:53:40,664 (46516/MainThread) pgcli.pgexecute ERROR - traceback: 'Traceback (most recent call last):\n  File "/usr/local/Cellar/pgcli/1.5.1/libexec/lib/python2.7/site-packages/pgcli/pgexecute.py", line 283, in run\n    for result in pgspecial.execute(cur, sql):\n  File "/usr/local/Cellar/pgcli/1.5.1/libexec/vendor/lib/python2.7/site-packages/pgspecial/main.py", line 88, in execute\n    return special_cmd.handler(cur=cur, pattern=pattern, verbose=verbose)\n  File "/usr/local/Cellar/pgcli/1.5.1/libexec/vendor/lib/python2.7/site-packages/pgspecial/iocommands.py", line 139, in copy\n    cur.copy_expert(\'copy \' + query, file)\nProgrammingError: relation "temp_endpoint_table" does not exist\n\n'
2017-05-17 15:54:10,037 (46548/MainThread) pgcli.main INFO - Default pager found in PAGER environment variable: 'less'
2017-05-17 15:54:36,230 (46548/MainThread) pgcli.pgexecute ERROR - sql: u'll\n', error: ProgrammingError('syntax error at or near "ll"\nLINE 1: ll\n        ^\n',)
2017-05-17 15:54:36,234 (46548/MainThread) pgcli.pgexecute ERROR - traceback: 'Traceback (most recent call last):\n  File "/usr/local/Cellar/pgcli/1.5.1/libexec/lib/python2.7/site-packages/pgcli/pgexecute.py", line 294, in run\n    yield self.execute_normal_sql(sql) + (sql, True)\n  File "/usr/local/Cellar/pgcli/1.5.1/libexec/lib/python2.7/site-packages/pgcli/pgexecute.py", line 314, in execute_normal_sql\n    cur.execute(split_sql)\nProgrammingError: syntax error at or near "ll"\nLINE 1: ll\n        ^\n\n'
2017-05-17 16:04:15,684 (46677/MainThread) pgcli.main INFO - Default pager found in PAGER environment variable: 'less'
2017-05-17 18:28:21,248 (47477/MainThread) pgcli.main INFO - Default pager found in PAGER environment variable: 'less'
2017-05-17 19:22:03,232 (47477/MainThread) pgcli.pgexecute ERROR - sql: u'select count(*) from subscriber where account_id = 68800', error: OperationalError('server closed the connection unexpectedly\n\tThis probably means the server terminated abnormally\n\tbefore or while processing the request.\n',)
2017-05-17 19:22:03,236 (47477/MainThread) pgcli.pgexecute ERROR - traceback: 'Traceback (most recent call last):\n  File "/usr/local/Cellar/pgcli/1.5.1/libexec/lib/python2.7/site-packages/pgcli/pgexecute.py", line 294, in run\n    yield self.execute_normal_sql(sql) + (sql, True)\n  File "/usr/local/Cellar/pgcli/1.5.1/libexec/lib/python2.7/site-packages/pgcli/pgexecute.py", line 314, in execute_normal_sql\n    cur.execute(split_sql)\n  File "/usr/local/Cellar/pgcli/1.5.1/libexec/lib/python2.7/site-packages/pgcli/pgexecute.py", line 39, in _wait_select\n    state = conn.poll()\nOperationalError: server closed the connection unexpectedly\n\tThis probably means the server terminated abnormally\n\tbefore or while processing the request.\n\n'
2017-05-17 19:22:03,236 (47477/MainThread) pgcli.main ERROR - sql: u'select count(*) from subscriber where account_id = 68800;', error: OperationalError('server closed the connection unexpectedly\n\tThis probably means the server terminated abnormally\n\tbefore or while processing the request.\n',)
2017-05-17 19:22:03,241 (47477/MainThread) pgcli.main ERROR - traceback: 'Traceback (most recent call last):\n  File "/usr/local/Cellar/pgcli/1.5.1/libexec/lib/python2.7/site-packages/pgcli/main.py", line 369, in execute_command\n    output, query = self._evaluate_command(text)\n  File "/usr/local/Cellar/pgcli/1.5.1/libexec/lib/python2.7/site-packages/pgcli/main.py", line 581, in _evaluate_command\n    for title, cur, headers, status, sql, success in res:\n  File "/usr/local/Cellar/pgcli/1.5.1/libexec/lib/python2.7/site-packages/pgcli/pgexecute.py", line 294, in run\n    yield self.execute_normal_sql(sql) + (sql, True)\n  File "/usr/local/Cellar/pgcli/1.5.1/libexec/lib/python2.7/site-packages/pgcli/pgexecute.py", line 314, in execute_normal_sql\n    cur.execute(split_sql)\n  File "/usr/local/Cellar/pgcli/1.5.1/libexec/lib/python2.7/site-packages/pgcli/pgexecute.py", line 39, in _wait_select\n    state = conn.poll()\nOperationalError: server closed the connection unexpectedly\n\tThis probably means the server terminated abnormally\n\tbefore or while processing the request.\n\n'
2017-05-17 19:23:47,156 (48304/MainThread) pgcli.main INFO - Default pager found in PAGER environment variable: 'less'
2017-05-17 20:01:39,962 (48743/MainThread) pgcli.main INFO - Default pager found in PAGER environment variable: 'less'
2017-05-17 20:27:21,865 (49000/MainThread) pgcli.main INFO - Default pager found in PAGER environment variable: 'less'
2017-05-17 20:28:03,782 (49000/MainThread) pgcli.pgexecute ERROR - sql: u'EXPLAIN analyze DELETE FROM subscriber where account_id = 6620', error: InternalError('cannot execute DELETE in a read-only transaction\n',)
2017-05-17 20:28:03,786 (49000/MainThread) pgcli.pgexecute ERROR - traceback: 'Traceback (most recent call last):\n  File "/usr/local/Cellar/pgcli/1.5.1/libexec/lib/python2.7/site-packages/pgcli/pgexecute.py", line 294, in run\n    yield self.execute_normal_sql(sql) + (sql, True)\n  File "/usr/local/Cellar/pgcli/1.5.1/libexec/lib/python2.7/site-packages/pgcli/pgexecute.py", line 314, in execute_normal_sql\n    cur.execute(split_sql)\nInternalError: cannot execute DELETE in a read-only transaction\n\n'
2017-05-17 22:47:18,717 (51133/MainThread) pgcli.main INFO - Default pager found in PAGER environment variable: 'less'
2017-05-18 19:25:21,710 (55388/MainThread) pgcli.main INFO - Default pager found in PAGER environment variable: 'less'
2017-05-18 19:30:18,710 (55388/MainThread) pgcli.pgexecute ERROR - sql: u"select * from plivo_billing_card_status where modified > '2017-05-17 00.00.00' limit 100", error: DataError('invalid input syntax for type timestamp: "2017-05-17 00.00.00"\nLINE 1: ...* from plivo_billing_card_status where modified > \'2017-05-1...\n                                                             ^\n',)
2017-05-18 19:30:18,714 (55388/MainThread) pgcli.pgexecute ERROR - traceback: 'Traceback (most recent call last):\n  File "/usr/local/Cellar/pgcli/1.5.1/libexec/lib/python2.7/site-packages/pgcli/pgexecute.py", line 294, in run\n    yield self.execute_normal_sql(sql) + (sql, True)\n  File "/usr/local/Cellar/pgcli/1.5.1/libexec/lib/python2.7/site-packages/pgcli/pgexecute.py", line 314, in execute_normal_sql\n    cur.execute(split_sql)\nDataError: invalid input syntax for type timestamp: "2017-05-17 00.00.00"\nLINE 1: ...* from plivo_billing_card_status where modified > \'2017-05-1...\n                                                             ^\n\n'
2017-05-18 19:37:57,688 (55388/MainThread) pgcli.pgexecute ERROR - sql: u"select * from plivo_billing_card_status where modified > '2017-05-17 00.00.00' limit 100", error: DataError('invalid input syntax for type timestamp: "2017-05-17 00.00.00"\nLINE 1: ...* from plivo_billing_card_status where modified > \'2017-05-1...\n                                                             ^\n',)
2017-05-18 19:37:57,689 (55388/MainThread) pgcli.pgexecute ERROR - traceback: 'Traceback (most recent call last):\n  File "/usr/local/Cellar/pgcli/1.5.1/libexec/lib/python2.7/site-packages/pgcli/pgexecute.py", line 294, in run\n    yield self.execute_normal_sql(sql) + (sql, True)\n  File "/usr/local/Cellar/pgcli/1.5.1/libexec/lib/python2.7/site-packages/pgcli/pgexecute.py", line 314, in execute_normal_sql\n    cur.execute(split_sql)\nDataError: invalid input syntax for type timestamp: "2017-05-17 00.00.00"\nLINE 1: ...* from plivo_billing_card_status where modified > \'2017-05-1...\n                                                             ^\n\n'
2017-05-18 19:38:05,409 (55388/MainThread) pgcli.pgexecute ERROR - sql: u"select * from plivo_billing_card_status where modified => '2017-05-17 00.00.00' limit 100", error: ProgrammingError('syntax error at or near "=>"\nLINE 1: ...t * from plivo_billing_card_status where modified => \'2017-0...\n                                                             ^\n',)
2017-05-18 19:38:05,410 (55388/MainThread) pgcli.pgexecute ERROR - traceback: 'Traceback (most recent call last):\n  File "/usr/local/Cellar/pgcli/1.5.1/libexec/lib/python2.7/site-packages/pgcli/pgexecute.py", line 294, in run\n    yield self.execute_normal_sql(sql) + (sql, True)\n  File "/usr/local/Cellar/pgcli/1.5.1/libexec/lib/python2.7/site-packages/pgcli/pgexecute.py", line 314, in execute_normal_sql\n    cur.execute(split_sql)\nProgrammingError: syntax error at or near "=>"\nLINE 1: ...t * from plivo_billing_card_status where modified => \'2017-0...\n                                                             ^\n\n'
2017-05-18 19:38:30,046 (55388/MainThread) pgcli.pgexecute ERROR - sql: u"select * from plivo_billing_card_status where modified > '2017-05-17 00.00.00' limit 100", error: DataError('invalid input syntax for type timestamp: "2017-05-17 00.00.00"\nLINE 1: ...* from plivo_billing_card_status where modified > \'2017-05-1...\n                                                             ^\n',)
2017-05-18 19:38:30,049 (55388/MainThread) pgcli.pgexecute ERROR - traceback: 'Traceback (most recent call last):\n  File "/usr/local/Cellar/pgcli/1.5.1/libexec/lib/python2.7/site-packages/pgcli/pgexecute.py", line 294, in run\n    yield self.execute_normal_sql(sql) + (sql, True)\n  File "/usr/local/Cellar/pgcli/1.5.1/libexec/lib/python2.7/site-packages/pgcli/pgexecute.py", line 314, in execute_normal_sql\n    cur.execute(split_sql)\nDataError: invalid input syntax for type timestamp: "2017-05-17 00.00.00"\nLINE 1: ...* from plivo_billing_card_status where modified > \'2017-05-1...\n                                                             ^\n\n'
2017-05-23 16:52:25,196 (75714/MainThread) pgcli.main INFO - Default pager found in PAGER environment variable: 'less'
2017-05-25 15:37:43,341 (84653/MainThread) pgcli.main INFO - Default pager found in PAGER environment variable: 'less'
2017-05-25 15:37:43,393 (84653/MainThread) pgcli.main ERROR - traceback: 'Traceback (most recent call last):\n  File "/usr/local/Cellar/pgcli/1.5.1/libexec/lib/python2.7/site-packages/pgcli/main.py", line 330, in connect\n    raise e\nOperationalError: could not connect to server: No such file or directory\n\tIs the server running locally and accepting\n\tconnections on Unix domain socket "/var/pgsql_socket/.s.PGSQL.5432"?\n\n'
2017-05-25 15:37:46,907 (84673/MainThread) pgcli.main INFO - Default pager found in PAGER environment variable: 'less'
2017-05-25 15:39:36,420 (84673/MainThread) pgcli.pgexecute ERROR - sql: u"select * from plivo_billing_card_status where account_id in (select id from plivo_account_account where user_id in (select id from auth_user where username = 'siliciomx'))", error: ProgrammingError('column "account_id" does not exist\nLINE 1: select * from plivo_billing_card_status where account_id in ...\n                                                      ^\n',)
2017-05-25 15:39:36,427 (84673/MainThread) pgcli.pgexecute ERROR - traceback: 'Traceback (most recent call last):\n  File "/usr/local/Cellar/pgcli/1.5.1/libexec/lib/python2.7/site-packages/pgcli/pgexecute.py", line 294, in run\n    yield self.execute_normal_sql(sql) + (sql, True)\n  File "/usr/local/Cellar/pgcli/1.5.1/libexec/lib/python2.7/site-packages/pgcli/pgexecute.py", line 314, in execute_normal_sql\n    cur.execute(split_sql)\nProgrammingError: column "account_id" does not exist\nLINE 1: select * from plivo_billing_card_status where account_id in ...\n                                                      ^\n\n'
2017-05-25 15:44:52,736 (84673/MainThread) pgcli.pgexecute ERROR - sql: u"delete from plivo_billing_card_verification_details where id = '26087'", error: InternalError('cannot execute DELETE in a read-only transaction\n',)
2017-05-25 15:44:52,739 (84673/MainThread) pgcli.pgexecute ERROR - traceback: 'Traceback (most recent call last):\n  File "/usr/local/Cellar/pgcli/1.5.1/libexec/lib/python2.7/site-packages/pgcli/pgexecute.py", line 294, in run\n    yield self.execute_normal_sql(sql) + (sql, True)\n  File "/usr/local/Cellar/pgcli/1.5.1/libexec/lib/python2.7/site-packages/pgcli/pgexecute.py", line 314, in execute_normal_sql\n    cur.execute(split_sql)\nInternalError: cannot execute DELETE in a read-only transaction\n\n'
2017-05-31 23:10:41,395 (12411/MainThread) pgcli.main INFO - Default pager found in PAGER environment variable: 'less'
2017-06-01 19:23:47,850 (29455/MainThread) pgcli.main INFO - Default pager found in PAGER environment variable: 'less'
2017-06-02 18:22:07,458 (37290/MainThread) pgcli.main INFO - Default pager found in PAGER environment variable: 'less'
2017-06-02 18:24:16,222 (37290/MainThread) pgcli.pgexecute ERROR - sql: u'EXPLAIN analyze SELECT "plivo_billing_incomingnumberrate"."id", "plivo_billing_incomingnumberrate"."product_plan_id", "plivo_billing_incomingnumberrate"."tier_id", "plivo_billing_incomingnumberrate"."effective_date", "plivo_billing_incomingnumberrate"."voice_unit", "plivo_billing_incomingnumberrate"."voice_rate", "plivo_billing_incomingnumberrate"."sms_unit", "plivo_billing_incomingnumberrate"."sms_rate", "plivo_billing_incomingnumberrate"."fax_unit", "plivo_billing_incomingnumberrate"."fax_rate", "plivo_billing_incomingnumberrate"."rental_unit", "plivo_billing_incomingnumberrate"."rental_rate", "plivo_billing_incomingnumberrate"."setup_rate" FROM "plivo_billing_incomingnumberrate" INNER JOIN "plivo_billing_tier" ON ("plivo_billing_incomingnumberrate"."tier_id" = "plivo_billing_tier"."id") WHERE ("plivo_billing_tier"."country_id" =   AND "plivo_billing_incomingnumberrate"."product_plan_id" = 1  AND NOT (("plivo_billing_incomingnumberrate"."sms_rate" < 0  OR "plivo_billing_incomingnumberrate"."voice_rate" < 0  OR "plivo_billing_incomingnumberrate"."rental_rate" < 0  OR "plivo_billing_incomingnumberrate"."setup_rate" < 0 )))', error: ProgrammingError('syntax error at or near "AND"\nLINE 1: ...id") WHERE ("plivo_billing_tier"."country_id" =   AND "plivo...\n                                                             ^\n',)
2017-06-02 18:24:16,226 (37290/MainThread) pgcli.pgexecute ERROR - traceback: 'Traceback (most recent call last):\n  File "/usr/local/Cellar/pgcli/1.5.1/libexec/lib/python2.7/site-packages/pgcli/pgexecute.py", line 294, in run\n    yield self.execute_normal_sql(sql) + (sql, True)\n  File "/usr/local/Cellar/pgcli/1.5.1/libexec/lib/python2.7/site-packages/pgcli/pgexecute.py", line 314, in execute_normal_sql\n    cur.execute(split_sql)\nProgrammingError: syntax error at or near "AND"\nLINE 1: ...id") WHERE ("plivo_billing_tier"."country_id" =   AND "plivo...\n                                                             ^\n\n'
2017-06-02 18:25:09,777 (37290/MainThread) pgcli.pgexecute ERROR - sql: u'EXPLAIN analyze SELECT "plivo_billing_incomingnumberrate"."id", "plivo_billing_incomingnumberrate"."product_plan_id", "plivo_billing_incomingnumberrate"."tier_id", "plivo_billing_incomingnumberrate"."effective_date", "plivo_billing_incomingnumberrate"."voice_unit", "plivo_billing_incomingnumberrate"."voice_rate", "plivo_billing_incomingnumberrate"."sms_unit", "plivo_billing_incomingnumberrate"."sms_rate", "plivo_billing_incomingnumberrate"."fax_unit", "plivo_billing_incomingnumberrate"."fax_rate", "plivo_billing_incomingnumberrate"."rental_unit", "plivo_billing_incomingnumberrate"."rental_rate", "plivo_billing_incomingnumberrate"."setup_rate" FROM "plivo_billing_incomingnumberrate" INNER JOIN "plivo_billing_tier" ON ("plivo_billing_incomingnumberrate"."tier_id" = "plivo_billing_tier"."id") WHERE ("plivo_billing_tier"."country_id" = 1  AND "plivo_billing_incomingnumberrate"."product_plan_id" = 1  AND NOT (("plivo_billing_incomingnumberrate"."sms_rate" < 0  OR "plivo_billing_incomingnumberrate"."voice_rate" < 0  OR "plivo_billing_incomingnumberrate"."rental_rate" < 0  OR "plivo_billing_incomingnumberrate"."setup_rate" < 0 )))', error: ProgrammingError('operator does not exist: character varying = integer\nLINE 1: ...r"."id") WHERE ("plivo_billing_tier"."country_id" = 1  AND "...\n                                                             ^\nHINT:  No operator matches the given name and argument type(s). You might need to add explicit type casts.\n',)
2017-06-02 18:25:09,778 (37290/MainThread) pgcli.pgexecute ERROR - traceback: 'Traceback (most recent call last):\n  File "/usr/local/Cellar/pgcli/1.5.1/libexec/lib/python2.7/site-packages/pgcli/pgexecute.py", line 294, in run\n    yield self.execute_normal_sql(sql) + (sql, True)\n  File "/usr/local/Cellar/pgcli/1.5.1/libexec/lib/python2.7/site-packages/pgcli/pgexecute.py", line 314, in execute_normal_sql\n    cur.execute(split_sql)\nProgrammingError: operator does not exist: character varying = integer\nLINE 1: ...r"."id") WHERE ("plivo_billing_tier"."country_id" = 1  AND "...\n                                                             ^\nHINT:  No operator matches the given name and argument type(s). You might need to add explicit type casts.\n\n'
2017-06-02 18:25:52,170 (37290/MainThread) pgcli.pgexecute ERROR - sql: u'EXPLAIN analyze SELECT "plivo_billing_incomingnumberrate"."id", "plivo_billing_incomingnumberrate"."product_plan_id", "plivo_billing_incomingnumberrate"."tier_id", "plivo_billing_incomingnumberrate"."effective_date", "plivo_billing_incomingnumberrate"."voice_unit", "plivo_billing_incomingnumberrate"."voice_rate", "plivo_billing_incomingnumberrate"."sms_unit", "plivo_billing_incomingnumberrate"."sms_rate", "plivo_billing_incomingnumberrate"."fax_unit", "plivo_billing_incomingnumberrate"."fax_rate", "plivo_billing_incomingnumberrate"."rental_unit", "plivo_billing_incomingnumberrate"."rental_rate", "plivo_billing_incomingnumberrate"."setup_rate" FROM "plivo_billing_incomingnumberrate" INNER JOIN "plivo_billing_tier" ON ("plivo_billing_incomingnumberrate"."tier_id" = "plivo_billing_tier"."id") WHERE ("plivo_billing_tier"."country_id" = "1"  AND "plivo_billing_incomingnumberrate"."product_plan_id" = 1  AND NOT (("plivo_billing_incomingnumberrate"."sms_rate" < 0  OR "plivo_billing_incomingnumberrate"."voice_rate" < 0  OR "plivo_billing_incomingnumberrate"."rental_rate" < 0  OR "plivo_billing_incomingnumberrate"."setup_rate" < 0 )))', error: ProgrammingError('column "1" does not exist\nLINE 1: ...."id") WHERE ("plivo_billing_tier"."country_id" = "1"  AND "...\n                                                             ^\n',)
2017-06-02 18:25:52,171 (37290/MainThread) pgcli.pgexecute ERROR - traceback: 'Traceback (most recent call last):\n  File "/usr/local/Cellar/pgcli/1.5.1/libexec/lib/python2.7/site-packages/pgcli/pgexecute.py", line 294, in run\n    yield self.execute_normal_sql(sql) + (sql, True)\n  File "/usr/local/Cellar/pgcli/1.5.1/libexec/lib/python2.7/site-packages/pgcli/pgexecute.py", line 314, in execute_normal_sql\n    cur.execute(split_sql)\nProgrammingError: column "1" does not exist\nLINE 1: ...."id") WHERE ("plivo_billing_tier"."country_id" = "1"  AND "...\n                                                             ^\n\n'
2017-06-02 18:26:56,888 (37290/MainThread) pgcli.pgexecute ERROR - sql: u'EXPLAIN analyze SELECT "plivo_billing_incomingnumberrate"."id", "plivo_billing_incomingnumberrate"."product_plan_id", "plivo_billing_incomingnumberrate"."tier_id", "plivo_billing_incomingnumberrate"."effective_date", "plivo_billing_incomingnumberrate"."voice_unit", "plivo_billing_incomingnumberrate"."voice_rate", "plivo_billing_incomingnumberrate"."sms_unit", "plivo_billing_incomingnumberrate"."sms_rate", "plivo_billing_incomingnumberrate"."fax_unit", "plivo_billing_incomingnumberrate"."fax_rate", "plivo_billing_incomingnumberrate"."rental_unit", "plivo_billing_incomingnumberrate"."rental_rate", "plivo_billing_incomingnumberrate"."setup_rate" FROM "plivo_billing_incomingnumberrate" INNER JOIN "plivo_billing_tier" ON ("plivo_billing_incomingnumberrate"."tier_id" = "plivo_billing_tier"."id") WHERE ("plivo_billing_tier"."country_id" = "US"  AND "plivo_billing_incomingnumberrate"."product_plan_id" = 1  AND NOT (("plivo_billing_incomingnumberrate"."sms_rate" < 0  OR "plivo_billing_incomingnumberrate"."voice_rate" < 0  OR "plivo_billing_incomingnumberrate"."rental_rate" < 0  OR "plivo_billing_incomingnumberrate"."setup_rate" < 0 )))', error: ProgrammingError('column "US" does not exist\nLINE 1: ...."id") WHERE ("plivo_billing_tier"."country_id" = "US"  AND ...\n                                                             ^\n',)
2017-06-02 18:26:56,888 (37290/MainThread) pgcli.pgexecute ERROR - traceback: 'Traceback (most recent call last):\n  File "/usr/local/Cellar/pgcli/1.5.1/libexec/lib/python2.7/site-packages/pgcli/pgexecute.py", line 294, in run\n    yield self.execute_normal_sql(sql) + (sql, True)\n  File "/usr/local/Cellar/pgcli/1.5.1/libexec/lib/python2.7/site-packages/pgcli/pgexecute.py", line 314, in execute_normal_sql\n    cur.execute(split_sql)\nProgrammingError: column "US" does not exist\nLINE 1: ...."id") WHERE ("plivo_billing_tier"."country_id" = "US"  AND ...\n                                                             ^\n\n'
2017-06-02 18:27:30,035 (37290/MainThread) pgcli.pgexecute ERROR - sql: u'EXPLAIN analyze SELECT "plivo_billing_incomingnumberrate"."id", "plivo_billing_incomingnumberrate"."product_plan_id", "plivo_billing_incomingnumberrate"."tier_id", "plivo_billing_incomingnumberrate"."effective_date", "plivo_billing_incomingnumberrate"."voice_unit", "plivo_billing_incomingnumberrate"."voice_rate", "plivo_billing_incomingnumberrate"."sms_unit", "plivo_billing_incomingnumberrate"."sms_rate", "plivo_billing_incomingnumberrate"."fax_unit", "plivo_billing_incomingnumberrate"."fax_rate", "plivo_billing_incomingnumberrate"."rental_unit", "plivo_billing_incomingnumberrate"."rental_rate", "plivo_billing_incomingnumberrate"."setup_rate" FROM "plivo_billing_incomingnumberrate" INNER JOIN "plivo_billing_tier" ON ("plivo_billing_incomingnumberrate"."tier_id" = "plivo_billing_tier"."id") WHERE ("plivo_billing_tier"."country_id" = "US"  AND "plivo_billing_incomingnumberrate"."product_plan_id" = 1  AND NOT (("plivo_billing_incomingnumberrate"."sms_rate" < 0  OR "plivo_billing_incomingnumberrate"."voice_rate" < 0  OR "plivo_billing_incomingnumberrate"."rental_rate" < 0  OR "plivo_billing_incomingnumberrate"."setup_rate" < 0 )))', error: ProgrammingError('column "US" does not exist\nLINE 1: ...."id") WHERE ("plivo_billing_tier"."country_id" = "US"  AND ...\n                                                             ^\n',)
2017-06-02 18:27:30,035 (37290/MainThread) pgcli.pgexecute ERROR - traceback: 'Traceback (most recent call last):\n  File "/usr/local/Cellar/pgcli/1.5.1/libexec/lib/python2.7/site-packages/pgcli/pgexecute.py", line 294, in run\n    yield self.execute_normal_sql(sql) + (sql, True)\n  File "/usr/local/Cellar/pgcli/1.5.1/libexec/lib/python2.7/site-packages/pgcli/pgexecute.py", line 314, in execute_normal_sql\n    cur.execute(split_sql)\nProgrammingError: column "US" does not exist\nLINE 1: ...."id") WHERE ("plivo_billing_tier"."country_id" = "US"  AND ...\n                                                             ^\n\n'
2017-06-02 18:29:09,191 (37290/MainThread) pgcli.pgexecute ERROR - sql: u'explain analyze SELECT "plivo_billing_incomingnumberrate"."id", "plivo_billing_incomingnumberrate"."product_plan_id", "plivo_billing_incomingnumberrate"."tier_id", "plivo_billing_incomingnumberrate"."effective_date", "plivo_billing_incomingnumberrate"."voice_unit", "plivo_billing_incomingnumberrate"."voice_rate", "plivo_billing_incomingnumberrate"."sms_unit", "plivo_billing_incomingnumberrate"."sms_rate", "plivo_billing_incomingnumberrate"."fax_unit", "plivo_billing_incomingnumberrate"."fax_rate", "plivo_billing_incomingnumberrate"."rental_unit", "plivo_billing_incomingnumberrate"."rental_rate", "plivo_billing_incomingnumberrate"."setup_rate" FROM "plivo_billing_incomingnumberrate" INNER JOIN "plivo_billing_tier" ON ("plivo_billing_incomingnumberrate"."tier_id" = "plivo_billing_tier"."id") WHERE ("plivo_billing_tier"."country_id" = \u201cUS\u201d   AND "plivo_billing_incomingnumberrate"."product_plan_id" = 1  AND NOT (("plivo_billing_incomingnumberrate"."sms_rate" < 0  OR "plivo_billing_incomingnumberrate"."voice_rate" < 0  OR "plivo_billing_incomingnumberrate"."rental_rate" < 0  OR "plivo_billing_incomingnumberrate"."setup_rate" < 0 )))', error: ProgrammingError('column "\xe2\x80\x9cus\xe2\x80\x9d" does not exist\nLINE 1: ...."id") WHERE ("plivo_billing_tier"."country_id" = \xe2\x80\x9cUS\xe2\x80\x9d   AND...\n                                                             ^\n',)
2017-06-02 18:29:09,192 (37290/MainThread) pgcli.pgexecute ERROR - traceback: 'Traceback (most recent call last):\n  File "/usr/local/Cellar/pgcli/1.5.1/libexec/lib/python2.7/site-packages/pgcli/pgexecute.py", line 294, in run\n    yield self.execute_normal_sql(sql) + (sql, True)\n  File "/usr/local/Cellar/pgcli/1.5.1/libexec/lib/python2.7/site-packages/pgcli/pgexecute.py", line 314, in execute_normal_sql\n    cur.execute(split_sql)\nProgrammingError: column "\xe2\x80\x9cus\xe2\x80\x9d" does not exist\nLINE 1: ...."id") WHERE ("plivo_billing_tier"."country_id" = \xe2\x80\x9cUS\xe2\x80\x9d   AND...\n                                                             ^\n\n'
2017-06-02 18:29:33,149 (37290/MainThread) pgcli.pgexecute ERROR - sql: u'explain analyze SELECT "plivo_billing_incomingnumberrate"."id", "plivo_billing_incomingnumberrate"."product_plan_id", "plivo_billing_incomingnumberrate"."tier_id", "plivo_billing_incomingnumberrate"."effective_date", "plivo_billing_incomingnumberrate"."voice_unit", "plivo_billing_incomingnumberrate"."voice_rate", "plivo_billing_incomingnumberrate"."sms_unit", "plivo_billing_incomingnumberrate"."sms_rate", "plivo_billing_incomingnumberrate"."fax_unit", "plivo_billing_incomingnumberrate"."fax_rate", "plivo_billing_incomingnumberrate"."rental_unit", "plivo_billing_incomingnumberrate"."rental_rate", "plivo_billing_incomingnumberrate"."setup_rate" FROM "plivo_billing_incomingnumberrate" INNER JOIN "plivo_billing_tier" ON ("plivo_billing_incomingnumberrate"."tier_id" = "plivo_billing_tier"."id") WHERE ("plivo_billing_tier"."country_id" = US   AND "plivo_billing_incomingnumberrate"."product_plan_id" = 1  AND NOT (("plivo_billing_incomingnumberrate"."sms_rate" < 0  OR "plivo_billing_incomingnumberrate"."voice_rate" < 0  OR "plivo_billing_incomingnumberrate"."rental_rate" < 0  OR "plivo_billing_incomingnumberrate"."setup_rate" < 0 )))', error: ProgrammingError('column "us" does not exist\nLINE 1: ...."id") WHERE ("plivo_billing_tier"."country_id" = US   AND "...\n                                                             ^\n',)
2017-06-02 18:29:33,149 (37290/MainThread) pgcli.pgexecute ERROR - traceback: 'Traceback (most recent call last):\n  File "/usr/local/Cellar/pgcli/1.5.1/libexec/lib/python2.7/site-packages/pgcli/pgexecute.py", line 294, in run\n    yield self.execute_normal_sql(sql) + (sql, True)\n  File "/usr/local/Cellar/pgcli/1.5.1/libexec/lib/python2.7/site-packages/pgcli/pgexecute.py", line 314, in execute_normal_sql\n    cur.execute(split_sql)\nProgrammingError: column "us" does not exist\nLINE 1: ...."id") WHERE ("plivo_billing_tier"."country_id" = US   AND "...\n                                                             ^\n\n'
2017-06-07 16:36:32,075 (79896/MainThread) pgcli.main INFO - Default pager found in PAGER environment variable: 'less'
2017-06-10 10:46:29,805 (93924/MainThread) pgcli.main INFO - No default pager found in environment. Using os default pager
2017-06-10 11:35:14,341 (94144/MainThread) pgcli.main INFO - No default pager found in environment. Using os default pager
2017-06-14 19:58:02,976 (4185/MainThread) pgcli.main INFO - No default pager found in environment. Using os default pager
2017-06-16 16:59:45,917 (7765/MainThread) pgcli.main INFO - No default pager found in environment. Using os default pager
2017-06-18 11:16:14,986 (11780/MainThread) pgcli.main INFO - No default pager found in environment. Using os default pager
2017-06-18 14:01:01,513 (11780/MainThread) pgcli.pgexecute ERROR - sql: u"select * from plivo_billing_paymentlog where charge_id = '\n    ch_ArgLZrVcIygnSm'", error: OperationalError('server closed the connection unexpectedly\n\tThis probably means the server terminated abnormally\n\tbefore or while processing the request.\n',)
2017-06-18 14:01:01,522 (11780/MainThread) pgcli.pgexecute ERROR - traceback: 'Traceback (most recent call last):\n  File "/usr/local/Cellar/pgcli/1.5.1/libexec/lib/python2.7/site-packages/pgcli/pgexecute.py", line 294, in run\n    yield self.execute_normal_sql(sql) + (sql, True)\n  File "/usr/local/Cellar/pgcli/1.5.1/libexec/lib/python2.7/site-packages/pgcli/pgexecute.py", line 314, in execute_normal_sql\n    cur.execute(split_sql)\nOperationalError: server closed the connection unexpectedly\n\tThis probably means the server terminated abnormally\n\tbefore or while processing the request.\n\n'
2017-06-18 14:01:01,523 (11780/MainThread) pgcli.main ERROR - sql: u"select * from plivo_billing_paymentlog where charge_id = '\n    ch_ArgLZrVcIygnSm';", error: OperationalError('server closed the connection unexpectedly\n\tThis probably means the server terminated abnormally\n\tbefore or while processing the request.\n',)
2017-06-18 14:01:01,526 (11780/MainThread) pgcli.main ERROR - traceback: 'Traceback (most recent call last):\n  File "/usr/local/Cellar/pgcli/1.5.1/libexec/lib/python2.7/site-packages/pgcli/main.py", line 369, in execute_command\n    output, query = self._evaluate_command(text)\n  File "/usr/local/Cellar/pgcli/1.5.1/libexec/lib/python2.7/site-packages/pgcli/main.py", line 581, in _evaluate_command\n    for title, cur, headers, status, sql, success in res:\n  File "/usr/local/Cellar/pgcli/1.5.1/libexec/lib/python2.7/site-packages/pgcli/pgexecute.py", line 294, in run\n    yield self.execute_normal_sql(sql) + (sql, True)\n  File "/usr/local/Cellar/pgcli/1.5.1/libexec/lib/python2.7/site-packages/pgcli/pgexecute.py", line 314, in execute_normal_sql\n    cur.execute(split_sql)\nOperationalError: server closed the connection unexpectedly\n\tThis probably means the server terminated abnormally\n\tbefore or while processing the request.\n\n'
2017-06-18 14:01:19,492 (11780/MainThread) pgcli.pgexecute ERROR - sql: u"select * from plivo_billing_paymentlog where charge_id = 'ch_ArgLZrVcIygnSm'", error: ProgrammingError('column "charge_id" does not exist\nLINE 1: select * from plivo_billing_paymentlog where charge_id = \'ch...\n                                                     ^\n',)
2017-06-18 14:01:19,493 (11780/MainThread) pgcli.pgexecute ERROR - traceback: 'Traceback (most recent call last):\n  File "/usr/local/Cellar/pgcli/1.5.1/libexec/lib/python2.7/site-packages/pgcli/pgexecute.py", line 294, in run\n    yield self.execute_normal_sql(sql) + (sql, True)\n  File "/usr/local/Cellar/pgcli/1.5.1/libexec/lib/python2.7/site-packages/pgcli/pgexecute.py", line 314, in execute_normal_sql\n    cur.execute(split_sql)\nProgrammingError: column "charge_id" does not exist\nLINE 1: select * from plivo_billing_paymentlog where charge_id = \'ch...\n                                                     ^\n\n'
2017-06-18 14:01:57,627 (11780/MainThread) pgcli.pgexecute ERROR - sql: u'select * plivo_billing_paymentlog limit 5', error: ProgrammingError('syntax error at or near "plivo_billing_paymentlog"\nLINE 1: select * plivo_billing_paymentlog limit 5\n                 ^\n',)
2017-06-18 14:01:57,627 (11780/MainThread) pgcli.pgexecute ERROR - traceback: 'Traceback (most recent call last):\n  File "/usr/local/Cellar/pgcli/1.5.1/libexec/lib/python2.7/site-packages/pgcli/pgexecute.py", line 294, in run\n    yield self.execute_normal_sql(sql) + (sql, True)\n  File "/usr/local/Cellar/pgcli/1.5.1/libexec/lib/python2.7/site-packages/pgcli/pgexecute.py", line 314, in execute_normal_sql\n    cur.execute(split_sql)\nProgrammingError: syntax error at or near "plivo_billing_paymentlog"\nLINE 1: select * plivo_billing_paymentlog limit 5\n                 ^\n\n'
2017-06-19 20:36:22,032 (16376/MainThread) pgcli.main INFO - No default pager found in environment. Using os default pager
2017-06-20 19:50:07,763 (27529/MainThread) pgcli.main INFO - No default pager found in environment. Using os default pager
2017-06-21 20:43:33,261 (30936/MainThread) pgcli.main INFO - No default pager found in environment. Using os default pager
2017-06-30 22:12:25,129 (51325/MainThread) pgcli.main INFO - No default pager found in environment. Using os default pager
2017-06-30 22:12:26,763 (51325/MainThread) pgcli.main ERROR - traceback: 'Traceback (most recent call last):\n  File "/usr/local/Cellar/pgcli/1.5.1/libexec/lib/python2.7/site-packages/pgcli/main.py", line 330, in connect\n    raise e\nOperationalError: FATAL:  password authentication failed for user "plivolog"\n\n'
2017-07-04 18:11:29,689 (79651/MainThread) pgcli.main INFO - No default pager found in environment. Using os default pager
2017-07-04 18:11:38,918 (79651/MainThread) pgcli.main ERROR - traceback: 'Traceback (most recent call last):\n  File "/usr/local/Cellar/pgcli/1.5.1/libexec/lib/python2.7/site-packages/pgcli/main.py", line 330, in connect\n    raise e\nOperationalError: asynchronous connection attempt underway\n'
2017-07-04 18:11:44,974 (79677/MainThread) pgcli.main INFO - No default pager found in environment. Using os default pager
2017-07-04 18:11:56,355 (79677/MainThread) pgcli.main ERROR - traceback: 'Traceback (most recent call last):\n  File "/usr/local/Cellar/pgcli/1.5.1/libexec/lib/python2.7/site-packages/pgcli/main.py", line 330, in connect\n    raise e\nOperationalError: FATAL:  password authentication failed for user "plivolog"\n\n'
